2018-06-08 22:02:23,382 - root -  ultratb : 147 - Internal Python error in the inspect module.
Below is the traceback from this internal error.

2018-06-08 22:02:23,391 - root -  ultratb : 1106 - 
Unfortunately, your original traceback can not be constructed.

